<?xml version="1.0" encoding="UTF-8"?>
<testng-results skipped="4" failed="2" total="8" passed="2">
  <reporter-output>
  </reporter-output>
  <suite name="Suite1" duration-ms="18016" started-at="2017-12-08T03:13:29Z" finished-at="2017-12-08T03:13:47Z">
    <groups>
    </groups>
    <test name="TEST1" duration-ms="18016" started-at="2017-12-08T03:13:29Z" finished-at="2017-12-08T03:13:47Z">
      <class name="com.demo.One.LoginTest">
        <test-method status="PASS" signature="doBeforeMethod()[pri:0, instance:com.demo.One.LoginTest@1593948d]" name="doBeforeMethod" is-config="true" duration-ms="4498" started-at="2017-12-08T11:13:42Z" finished-at="2017-12-08T11:13:46Z">
          <reporter-output>
          </reporter-output>
        </test-method> <!-- doBeforeMethod -->
        <test-method status="FAIL" signature="test50()[pri:0, instance:com.demo.One.LoginTest@1593948d]" name="test50" duration-ms="78" started-at="2017-12-08T11:13:46Z" finished-at="2017-12-08T11:13:46Z">
          <exception class="java.lang.AssertionError">
            <message>
              <![CDATA[expected [true] but found [false]]]>
            </message>
            <full-stacktrace>
              <![CDATA[java.lang.AssertionError: expected [true] but found [false]
	at org.testng.Assert.fail(Assert.java:94)
	at org.testng.Assert.failNotEquals(Assert.java:496)
	at org.testng.Assert.assertTrue(Assert.java:42)
	at org.testng.Assert.assertTrue(Assert.java:52)
	at com.demo.One.LoginTest.test50(LoginTest.java:19)
	at sun.reflect.NativeMethodAccessorImpl.invoke0(Native Method)
	at sun.reflect.NativeMethodAccessorImpl.invoke(Unknown Source)
	at sun.reflect.DelegatingMethodAccessorImpl.invoke(Unknown Source)
	at java.lang.reflect.Method.invoke(Unknown Source)
	at org.testng.internal.MethodInvocationHelper.invokeMethod(MethodInvocationHelper.java:85)
	at org.testng.internal.Invoker.invokeMethod(Invoker.java:639)
	at org.testng.internal.Invoker.invokeTestMethod(Invoker.java:816)
	at org.testng.internal.Invoker.invokeTestMethods(Invoker.java:1124)
	at org.testng.internal.TestMethodWorker.invokeTestMethods(TestMethodWorker.java:125)
	at org.testng.internal.TestMethodWorker.run(TestMethodWorker.java:108)
	at org.testng.TestRunner.privateRun(TestRunner.java:774)
	at org.testng.TestRunner.run(TestRunner.java:624)
	at org.testng.SuiteRunner.runTest(SuiteRunner.java:359)
	at org.testng.SuiteRunner.runSequentially(SuiteRunner.java:354)
	at org.testng.SuiteRunner.privateRun(SuiteRunner.java:312)
	at org.testng.SuiteRunner.run(SuiteRunner.java:261)
	at org.testng.SuiteRunnerWorker.runSuite(SuiteRunnerWorker.java:52)
	at org.testng.SuiteRunnerWorker.run(SuiteRunnerWorker.java:86)
	at org.testng.TestNG.runSuitesSequentially(TestNG.java:1215)
	at org.testng.TestNG.runSuitesLocally(TestNG.java:1140)
	at org.testng.TestNG.run(TestNG.java:1048)
	at org.testng.remote.AbstractRemoteTestNG.run(AbstractRemoteTestNG.java:114)
	at org.testng.remote.RemoteTestNG.initAndRun(RemoteTestNG.java:251)
	at org.testng.remote.RemoteTestNG.main(RemoteTestNG.java:77)
]]>
            </full-stacktrace>
          </exception> <!-- java.lang.AssertionError -->
          <reporter-output>
          </reporter-output>
        </test-method> <!-- test50 -->
        <test-method status="FAIL" signature="test2()[pri:0, instance:com.demo.One.LoginTest@1593948d]" name="test2" duration-ms="31" started-at="2017-12-08T11:13:46Z" finished-at="2017-12-08T11:13:46Z">
          <exception class="java.lang.AssertionError">
            <message>
              <![CDATA[expected [true] but found [false]]]>
            </message>
            <full-stacktrace>
              <![CDATA[java.lang.AssertionError: expected [true] but found [false]
	at org.testng.Assert.fail(Assert.java:94)
	at org.testng.Assert.failNotEquals(Assert.java:496)
	at org.testng.Assert.assertTrue(Assert.java:42)
	at org.testng.Assert.assertTrue(Assert.java:52)
	at com.demo.One.LoginTest.test2(LoginTest.java:36)
	at sun.reflect.NativeMethodAccessorImpl.invoke0(Native Method)
	at sun.reflect.NativeMethodAccessorImpl.invoke(Unknown Source)
	at sun.reflect.DelegatingMethodAccessorImpl.invoke(Unknown Source)
	at java.lang.reflect.Method.invoke(Unknown Source)
	at org.testng.internal.MethodInvocationHelper.invokeMethod(MethodInvocationHelper.java:85)
	at org.testng.internal.Invoker.invokeMethod(Invoker.java:639)
	at org.testng.internal.Invoker.invokeTestMethod(Invoker.java:816)
	at org.testng.internal.Invoker.invokeTestMethods(Invoker.java:1124)
	at org.testng.internal.TestMethodWorker.invokeTestMethods(TestMethodWorker.java:125)
	at org.testng.internal.TestMethodWorker.run(TestMethodWorker.java:108)
	at org.testng.TestRunner.privateRun(TestRunner.java:774)
	at org.testng.TestRunner.run(TestRunner.java:624)
	at org.testng.SuiteRunner.runTest(SuiteRunner.java:359)
	at org.testng.SuiteRunner.runSequentially(SuiteRunner.java:354)
	at org.testng.SuiteRunner.privateRun(SuiteRunner.java:312)
	at org.testng.SuiteRunner.run(SuiteRunner.java:261)
	at org.testng.SuiteRunnerWorker.runSuite(SuiteRunnerWorker.java:52)
	at org.testng.SuiteRunnerWorker.run(SuiteRunnerWorker.java:86)
	at org.testng.TestNG.runSuitesSequentially(TestNG.java:1215)
	at org.testng.TestNG.runSuitesLocally(TestNG.java:1140)
	at org.testng.TestNG.run(TestNG.java:1048)
	at org.testng.remote.AbstractRemoteTestNG.run(AbstractRemoteTestNG.java:114)
	at org.testng.remote.RemoteTestNG.initAndRun(RemoteTestNG.java:251)
	at org.testng.remote.RemoteTestNG.main(RemoteTestNG.java:77)
]]>
            </full-stacktrace>
          </exception> <!-- java.lang.AssertionError -->
          <reporter-output>
          </reporter-output>
        </test-method> <!-- test2 -->
        <test-method status="SKIP" signature="test6()[pri:0, instance:com.demo.One.LoginTest@1593948d]" name="test6" duration-ms="0" started-at="2017-12-08T11:13:46Z" depends-on-methods="com.demo.One.LoginTest.test2" finished-at="2017-12-08T11:13:46Z">
          <exception class="java.lang.Throwable">
            <message>
              <![CDATA[Method LoginTest.test6()[pri:0, instance:com.demo.One.LoginTest@1593948d] depends on not successfully finished methods]]>
            </message>
            <full-stacktrace>
              <![CDATA[java.lang.Throwable: Method LoginTest.test6()[pri:0, instance:com.demo.One.LoginTest@1593948d] depends on not successfully finished methods
	at org.testng.internal.Invoker.invokeTestMethods(Invoker.java:1033)
	at org.testng.internal.TestMethodWorker.invokeTestMethods(TestMethodWorker.java:125)
	at org.testng.internal.TestMethodWorker.run(TestMethodWorker.java:108)
	at org.testng.TestRunner.privateRun(TestRunner.java:774)
	at org.testng.TestRunner.run(TestRunner.java:624)
	at org.testng.SuiteRunner.runTest(SuiteRunner.java:359)
	at org.testng.SuiteRunner.runSequentially(SuiteRunner.java:354)
	at org.testng.SuiteRunner.privateRun(SuiteRunner.java:312)
	at org.testng.SuiteRunner.run(SuiteRunner.java:261)
	at org.testng.SuiteRunnerWorker.runSuite(SuiteRunnerWorker.java:52)
	at org.testng.SuiteRunnerWorker.run(SuiteRunnerWorker.java:86)
	at org.testng.TestNG.runSuitesSequentially(TestNG.java:1215)
	at org.testng.TestNG.runSuitesLocally(TestNG.java:1140)
	at org.testng.TestNG.run(TestNG.java:1048)
	at org.testng.remote.AbstractRemoteTestNG.run(AbstractRemoteTestNG.java:114)
	at org.testng.remote.RemoteTestNG.initAndRun(RemoteTestNG.java:251)
	at org.testng.remote.RemoteTestNG.main(RemoteTestNG.java:77)
]]>
            </full-stacktrace>
          </exception> <!-- java.lang.Throwable -->
          <reporter-output>
          </reporter-output>
        </test-method> <!-- test6 -->
        <test-method status="SKIP" signature="test4()[pri:0, instance:com.demo.One.LoginTest@1593948d]" name="test4" duration-ms="0" started-at="2017-12-08T11:13:46Z" depends-on-methods="com.demo.One.LoginTest.test2" finished-at="2017-12-08T11:13:46Z">
          <exception class="java.lang.Throwable">
            <message>
              <![CDATA[Method LoginTest.test4()[pri:0, instance:com.demo.One.LoginTest@1593948d] depends on not successfully finished methods]]>
            </message>
            <full-stacktrace>
              <![CDATA[java.lang.Throwable: Method LoginTest.test4()[pri:0, instance:com.demo.One.LoginTest@1593948d] depends on not successfully finished methods
	at org.testng.internal.Invoker.invokeTestMethods(Invoker.java:1033)
	at org.testng.internal.TestMethodWorker.invokeTestMethods(TestMethodWorker.java:125)
	at org.testng.internal.TestMethodWorker.run(TestMethodWorker.java:108)
	at org.testng.TestRunner.privateRun(TestRunner.java:774)
	at org.testng.TestRunner.run(TestRunner.java:624)
	at org.testng.SuiteRunner.runTest(SuiteRunner.java:359)
	at org.testng.SuiteRunner.runSequentially(SuiteRunner.java:354)
	at org.testng.SuiteRunner.privateRun(SuiteRunner.java:312)
	at org.testng.SuiteRunner.run(SuiteRunner.java:261)
	at org.testng.SuiteRunnerWorker.runSuite(SuiteRunnerWorker.java:52)
	at org.testng.SuiteRunnerWorker.run(SuiteRunnerWorker.java:86)
	at org.testng.TestNG.runSuitesSequentially(TestNG.java:1215)
	at org.testng.TestNG.runSuitesLocally(TestNG.java:1140)
	at org.testng.TestNG.run(TestNG.java:1048)
	at org.testng.remote.AbstractRemoteTestNG.run(AbstractRemoteTestNG.java:114)
	at org.testng.remote.RemoteTestNG.initAndRun(RemoteTestNG.java:251)
	at org.testng.remote.RemoteTestNG.main(RemoteTestNG.java:77)
]]>
            </full-stacktrace>
          </exception> <!-- java.lang.Throwable -->
          <reporter-output>
          </reporter-output>
        </test-method> <!-- test4 -->
        <test-method status="SKIP" signature="test5()[pri:0, instance:com.demo.One.LoginTest@1593948d]" name="test5" duration-ms="0" started-at="2017-12-08T11:13:46Z" depends-on-methods="com.demo.One.LoginTest.test2" finished-at="2017-12-08T11:13:46Z">
          <exception class="java.lang.Throwable">
            <message>
              <![CDATA[Method LoginTest.test5()[pri:0, instance:com.demo.One.LoginTest@1593948d] depends on not successfully finished methods]]>
            </message>
            <full-stacktrace>
              <![CDATA[java.lang.Throwable: Method LoginTest.test5()[pri:0, instance:com.demo.One.LoginTest@1593948d] depends on not successfully finished methods
	at org.testng.internal.Invoker.invokeTestMethods(Invoker.java:1033)
	at org.testng.internal.TestMethodWorker.invokeTestMethods(TestMethodWorker.java:125)
	at org.testng.internal.TestMethodWorker.run(TestMethodWorker.java:108)
	at org.testng.TestRunner.privateRun(TestRunner.java:774)
	at org.testng.TestRunner.run(TestRunner.java:624)
	at org.testng.SuiteRunner.runTest(SuiteRunner.java:359)
	at org.testng.SuiteRunner.runSequentially(SuiteRunner.java:354)
	at org.testng.SuiteRunner.privateRun(SuiteRunner.java:312)
	at org.testng.SuiteRunner.run(SuiteRunner.java:261)
	at org.testng.SuiteRunnerWorker.runSuite(SuiteRunnerWorker.java:52)
	at org.testng.SuiteRunnerWorker.run(SuiteRunnerWorker.java:86)
	at org.testng.TestNG.runSuitesSequentially(TestNG.java:1215)
	at org.testng.TestNG.runSuitesLocally(TestNG.java:1140)
	at org.testng.TestNG.run(TestNG.java:1048)
	at org.testng.remote.AbstractRemoteTestNG.run(AbstractRemoteTestNG.java:114)
	at org.testng.remote.RemoteTestNG.initAndRun(RemoteTestNG.java:251)
	at org.testng.remote.RemoteTestNG.main(RemoteTestNG.java:77)
]]>
            </full-stacktrace>
          </exception> <!-- java.lang.Throwable -->
          <reporter-output>
          </reporter-output>
        </test-method> <!-- test5 -->
        <test-method status="SKIP" signature="test3()[pri:0, instance:com.demo.One.LoginTest@1593948d]" name="test3" duration-ms="0" started-at="2017-12-08T11:13:46Z" depends-on-methods="com.demo.One.LoginTest.test2" finished-at="2017-12-08T11:13:46Z">
          <exception class="java.lang.Throwable">
            <message>
              <![CDATA[Method LoginTest.test3()[pri:0, instance:com.demo.One.LoginTest@1593948d] depends on not successfully finished methods]]>
            </message>
            <full-stacktrace>
              <![CDATA[java.lang.Throwable: Method LoginTest.test3()[pri:0, instance:com.demo.One.LoginTest@1593948d] depends on not successfully finished methods
	at org.testng.internal.Invoker.invokeTestMethods(Invoker.java:1033)
	at org.testng.internal.TestMethodWorker.invokeTestMethods(TestMethodWorker.java:125)
	at org.testng.internal.TestMethodWorker.run(TestMethodWorker.java:108)
	at org.testng.TestRunner.privateRun(TestRunner.java:774)
	at org.testng.TestRunner.run(TestRunner.java:624)
	at org.testng.SuiteRunner.runTest(SuiteRunner.java:359)
	at org.testng.SuiteRunner.runSequentially(SuiteRunner.java:354)
	at org.testng.SuiteRunner.privateRun(SuiteRunner.java:312)
	at org.testng.SuiteRunner.run(SuiteRunner.java:261)
	at org.testng.SuiteRunnerWorker.runSuite(SuiteRunnerWorker.java:52)
	at org.testng.SuiteRunnerWorker.run(SuiteRunnerWorker.java:86)
	at org.testng.TestNG.runSuitesSequentially(TestNG.java:1215)
	at org.testng.TestNG.runSuitesLocally(TestNG.java:1140)
	at org.testng.TestNG.run(TestNG.java:1048)
	at org.testng.remote.AbstractRemoteTestNG.run(AbstractRemoteTestNG.java:114)
	at org.testng.remote.RemoteTestNG.initAndRun(RemoteTestNG.java:251)
	at org.testng.remote.RemoteTestNG.main(RemoteTestNG.java:77)
]]>
            </full-stacktrace>
          </exception> <!-- java.lang.Throwable -->
          <reporter-output>
          </reporter-output>
        </test-method> <!-- test3 -->
        <test-method status="PASS" signature="doAfterMethod()[pri:0, instance:com.demo.One.LoginTest@1593948d]" name="doAfterMethod" is-config="true" duration-ms="1015" started-at="2017-12-08T11:13:46Z" finished-at="2017-12-08T11:13:47Z">
          <reporter-output>
          </reporter-output>
        </test-method> <!-- doAfterMethod -->
      </class> <!-- com.demo.One.LoginTest -->
      <class name="com.demo.Three.ObjectPageTest">
        <test-method status="PASS" signature="doBeforeMethod()[pri:0, instance:com.demo.Three.ObjectPageTest@482f8f11]" name="doBeforeMethod" is-config="true" duration-ms="6097" started-at="2017-12-08T11:13:29Z" finished-at="2017-12-08T11:13:36Z">
          <reporter-output>
          </reporter-output>
        </test-method> <!-- doBeforeMethod -->
        <test-method status="PASS" signature="test1()[pri:0, instance:com.demo.Three.ObjectPageTest@482f8f11]" name="test1" duration-ms="2864" started-at="2017-12-08T11:13:36Z" finished-at="2017-12-08T11:13:38Z">
          <reporter-output>
          </reporter-output>
        </test-method> <!-- test1 -->
        <test-method status="PASS" signature="test()[pri:0, instance:com.demo.Three.ObjectPageTest@482f8f11]" name="test" duration-ms="2602" started-at="2017-12-08T11:13:38Z" finished-at="2017-12-08T11:13:41Z">
          <reporter-output>
          </reporter-output>
        </test-method> <!-- test -->
        <test-method status="PASS" signature="doAfterMethod()[pri:0, instance:com.demo.Three.ObjectPageTest@482f8f11]" name="doAfterMethod" is-config="true" duration-ms="810" started-at="2017-12-08T11:13:41Z" finished-at="2017-12-08T11:13:42Z">
          <reporter-output>
          </reporter-output>
        </test-method> <!-- doAfterMethod -->
      </class> <!-- com.demo.Three.ObjectPageTest -->
    </test> <!-- TEST1 -->
  </suite> <!-- Suite1 -->
</testng-results>
